Workbook

Sheet Cover
B2: Bank Counterparty Credit Scoring Model
B3: Author: Jamal Kanbarieh · Built for portfolio demonstration using public disclosures
B5: Purpose | C5: Assigns an internal credit grade and an indicative probability of default (PD) to a bank counterparty, as used by a financial-institutions desk to set interbank and trade-finance limits.
B7: Approach | C7: CAMELS-style scorecard: 9 ratios across Capital, Asset quality, Profitability, Liquidity and Efficiency. Each ratio is graded A (1 point, strongest) to E (5 points) against thresholds; category weights give a score from 1 to 5, which maps to a rating scale and PD. An optional sovereign ceiling caps the final rating.
B9: How to use | C9: 1) On "Inputs", choose a bank in the yellow cell C4 (data is pulled from "Peer Data"). 2) Optionally type over any figure in the yellow override column. 3) Read the result on "Scorecard". 4) "Peer Ranking" scores every bank at once. 5) Thresholds, weights and the rating scale are editable on "Assumptions".
B11: Colour legend | C11: Blue text = hard-coded input · Black = formula · Green = link to another sheet · Yellow fill = cell for you to choose/override.
B13: Data source | C13: Public quarterly financial statements of Syrian private banks (Q4 2024), published by the Syrian Commission on Financial Markets and Securities (scfms.sy/en/declaration). Figures in SYP millions. Net income and operating income exclude unrealised structural FX revaluation.
B15: Calibration | C15: Thresholds, weights and the score-to-rating-to-PD mapping are the author's own illustrative calibration. They are not an official methodology of any bank or rating agency, and the PDs are not historical default statistics.
B17: Disclaimer | C17: Demonstration model only. Not a credit opinion or investment advice.
B20: Example input format | C20: Inputs!C4 = "QNBS" (bank code from the list) · Inputs!C7 = 12 (months covered by the income statement) · overrides in SYP millions, e.g. 3,517,320

Sheet Inputs
A1: Inputs
A2: Choose a bank in C4. Figures are pulled from "Peer Data"; type a value in the yellow Override column to replace any of them. SYP millions.
B4: Bank code | C4: QNBS
B5: Bank name | C5: =IFERROR(INDEX('Peer Data'!$B$5:$B$16,MATCH($C$4,'Peer Data'!$A$5:$A$16,0)),"Code not found") -> QNB Syria
B6: Period | C6: =IFERROR(INDEX('Peer Data'!$C$5:$C$16,MATCH($C$4,'Peer Data'!$A$5:$A$16,0)),"") -> Q4 2024
B7: Months in income period | C7: 12
B8: Sovereign ceiling | C8: None
A10: Item | B10: From Peer Data | C10: Override | D10: Value used | E10: Unit
A11: Total assets | B11: =IFERROR(INDEX('Peer Data'!$D$5:$D$16,MATCH($C$4,'Peer Data'!$A$5:$A$16,0)),0) -> 3517320.5 | D11: =IF(C11="",B11,C11) -> 3517320.5 | E11: SYP mn
A12: Liquid assets | B12: =IFERROR(INDEX('Peer Data'!$E$5:$E$16,MATCH($C$4,'Peer Data'!$A$5:$A$16,0)),0) -> 552230 | D12: =IF(C12="",B12,C12) -> 552230 | E12: SYP mn
A13: Gross loans (direct facilities) | B13: =IFERROR(INDEX('Peer Data'!$F$5:$F$16,MATCH($C$4,'Peer Data'!$A$5:$A$16,0)),0) -> 175731 | D13: =IF(C13="",B13,C13) -> 175731 | E13: SYP mn
A14: Non-performing loans | B14: =IFERROR(INDEX('Peer Data'!$G$5:$G$16,MATCH($C$4,'Peer Data'!$A$5:$A$16,0)),0) -> 0 | D14: =IF(C14="",B14,C14) -> 0 | E14: SYP mn
A15: ECL provisions on loans | B15: =IFERROR(INDEX('Peer Data'!$H$5:$H$16,MATCH($C$4,'Peer Data'!$A$5:$A$16,0)),0) -> 867.5 | D15: =IF(C15="",B15,C15) -> 867.5 | E15: SYP mn
A16: Customer deposits | B16: =IFERROR(INDEX('Peer Data'!$I$5:$I$16,MATCH($C$4,'Peer Data'!$A$5:$A$16,0)),0) -> 853242.3 | D16: =IF(C16="",B16,C16) -> 853242.3 | E16: SYP mn
A17: Cash margins | B17: =IFERROR(INDEX('Peer Data'!$J$5:$J$16,MATCH($C$4,'Peer Data'!$A$5:$A$16,0)),0) -> 19594.8 | D17: =IF(C17="",B17,C17) -> 19594.8 | E17: SYP mn
A18: Total liabilities | B18: =IFERROR(INDEX('Peer Data'!$K$5:$K$16,MATCH($C$4,'Peer Data'!$A$5:$A$16,0)),0) -> 1142094.5 | D18: =IF(C18="",B18,C18) -> 1142094.5 | E18: SYP mn
A19: Total equity | B19: =IFERROR(INDEX('Peer Data'!$L$5:$L$16,MATCH($C$4,'Peer Data'!$A$5:$A$16,0)),0) -> 2375225.9 | D19: =IF(C19="",B19,C19) -> 2375225.9 | E19: SYP mn
A20: Regulatory capital | B20: =IFERROR(INDEX('Peer Data'!$M$5:$M$16,MATCH($C$4,'Peer Data'!$A$5:$A$16,0)),0) -> 2374047.7 | D20: =IF(C20="",B20,C20) -> 2374047.7 | E20: SYP mn
A21: Risk-weighted assets | B21: =IFERROR(INDEX('Peer Data'!$N$5:$N$16,MATCH($C$4,'Peer Data'!$A$5:$A$16,0)),0) -> 1150082.8 | D21: =IF(C21="",B21,C21) -> 1150082.8 | E21: SYP mn
A22: Operating income (adj.) | B22: =IFERROR(INDEX('Peer Data'!$O$5:$O$16,MATCH($C$4,'Peer Data'!$A$5:$A$16,0)),0) -> 132974.7 | D22: =IF(C22="",B22,C22) -> 132974.7 | E22: SYP mn
A23: Operating expenses (excl. ECL) | B23: =IFERROR(INDEX('Peer Data'!$P$5:$P$16,MATCH($C$4,'Peer Data'!$A$5:$A$16,0)),0) -> 63692 | D23: =IF(C23="",B23,C23) -> 63692 | E23: SYP mn
A24: Net income (adj.) | B24: =IFERROR(INDEX('Peer Data'!$Q$5:$Q$16,MATCH($C$4,'Peer Data'!$A$5:$A$16,0)),0) -> 64696.2 | D24: =IF(C24="",B24,C24) -> 64696.2 | E24: SYP mn

Sheet Scorecard
A1: Credit scorecard
A2: =Inputs!C5&" ("&Inputs!C4&") · "&Inputs!C6 -> QNB Syria (QNBS) · Q4 2024
A4: Ratio | B4: Category | C4: Value | D4: Points (1–5) | E4: Grade | F4: Weight | G4: Weighted points
A5: =Assumptions!A5 -> Capital adequacy ratio (CAR) | B5: =Assumptions!B5 -> Capital | C5: =IF(Inputs!$D$21<=0,"n.m.",Inputs!$D$20/Inputs!$D$21) -> 2.0642407 | D5: =IF(ISNUMBER(C5),IF(Assumptions!$C$5="Higher",IF(C5>=Assumptions!$D$5,1,IF(C5>=Assumptions!$E$5,2,IF(C5>=Assumptions!$F$5,3,IF(C5>=Assumptions!$G$5,4,5)))),IF(C5<=Assumptions!$D$5,1,IF(C5<=Assumptions!$E$5,2,IF(C5<=Assumptions!$F$5,3,IF(C5<=Assumptions!$G$5,4,5))))),5) -> 1 | E5: =CHAR(64+D5) -> A | F5: =Assumptions!H5 -> 0.1 | G5: =D5*F5 -> 0.1
A6: =Assumptions!A6 -> Equity / RWA | B6: =Assumptions!B6 -> Capital | C6: =IF(Inputs!$D$21<=0,"n.m.",Inputs!$D$19/Inputs!$D$21) -> 2.0652651 | D6: =IF(ISNUMBER(C6),IF(Assumptions!$C$6="Higher",IF(C6>=Assumptions!$D$6,1,IF(C6>=Assumptions!$E$6,2,IF(C6>=Assumptions!$F$6,3,IF(C6>=Assumptions!$G$6,4,5)))),IF(C6<=Assumptions!$D$6,1,IF(C6<=Assumptions!$E$6,2,IF(C6<=Assumptions!$F$6,3,IF(C6<=Assumptions!$G$6,4,5))))),5) -> 1 | E6: =CHAR(64+D6) -> A | F6: =Assumptions!H6 -> 0.1 | G6: =D6*F6 -> 0.1
A7: =Assumptions!A7 -> NPL ratio | B7: =Assumptions!B7 -> Asset quality | C7: =IF(Inputs!$D$13<=0,"n.m.",Inputs!$D$14/Inputs!$D$13) -> 0 | D7: =IF(ISNUMBER(C7),IF(Assumptions!$C$7="Higher",IF(C7>=Assumptions!$D$7,1,IF(C7>=Assumptions!$E$7,2,IF(C7>=Assumptions!$F$7,3,IF(C7>=Assumptions!$G$7,4,5)))),IF(C7<=Assumptions!$D$7,1,IF(C7<=Assumptions!$E$7,2,IF(C7<=Assumptions!$F$7,3,IF(C7<=Assumptions!$G$7,4,5))))),5) -> 1 | E7: =CHAR(64+D7) -> A | F7: =Assumptions!H7 -> 0.15 | G7: =D7*F7 -> 0.15
A8: =Assumptions!A8 -> NPL / (equity + ECL) | B8: =Assumptions!B8 -> Asset quality | C8: =IF((Inputs!$D$19+Inputs!$D$15)<=0,"n.m.",Inputs!$D$14/(Inputs!$D$19+Inputs!$D$15)) -> 0 | D8: =IF(ISNUMBER(C8),IF(Assumptions!$C$8="Higher",IF(C8>=Assumptions!$D$8,1,IF(C8>=Assumptions!$E$8,2,IF(C8>=Assumptions!$F$8,3,IF(C8>=Assumptions!$G$8,4,5)))),IF(C8<=Assumptions!$D$8,1,IF(C8<=Assumptions!$E$8,2,IF(C8<=Assumptions!$F$8,3,IF(C8<=Assumptions!$G$8,4,5))))),5) -> 1 | E8: =CHAR(64+D8) -> A | F8: =Assumptions!H8 -> 0.15 | G8: =D8*F8 -> 0.15
A9: =Assumptions!A9 -> Net income / RWA (annualised) | B9: =Assumptions!B9 -> Profitability | C9: =IF(Inputs!$D$21<=0,"n.m.",Inputs!$D$24*12/Inputs!$C$7/Inputs!$D$21) -> 0.056253515 | D9: =IF(ISNUMBER(C9),IF(Assumptions!$C$9="Higher",IF(C9>=Assumptions!$D$9,1,IF(C9>=Assumptions!$E$9,2,IF(C9>=Assumptions!$F$9,3,IF(C9>=Assumptions!$G$9,4,5)))),IF(C9<=Assumptions!$D$9,1,IF(C9<=Assumptions!$E$9,2,IF(C9<=Assumptions!$F$9,3,IF(C9<=Assumptions!$G$9,4,5))))),5) -> 1 | E9: =CHAR(64+D9) -> A | F9: =Assumptions!H9 -> 0.1 | G9: =D9*F9 -> 0.1
A10: =Assumptions!A10 -> Pre-provision profit / RWA (ann.) | B10: =Assumptions!B10 -> Profitability | C10: =IF(Inputs!$D$21<=0,"n.m.",(Inputs!$D$22-Inputs!$D$23)*12/Inputs!$C$7/Inputs!$D$21) -> 0.060241489 | D10: =IF(ISNUMBER(C10),IF(Assumptions!$C$10="Higher",IF(C10>=Assumptions!$D$10,1,IF(C10>=Assumptions!$E$10,2,IF(C10>=Assumptions!$F$10,3,IF(C10>=Assumptions!$G$10,4,5)))),IF(C10<=Assumptions!$D$10,1,IF(C10<=Assumptions!$E$10,2,IF(C10<=Assumptions!$F$10,3,IF(C10<=Assumptions!$G$10,4,5))))),5) -> 1 | E10: =CHAR(64+D10) -> A | F10: =Assumptions!H10 -> 0.1 | G10: =D10*F10 -> 0.1
A11: =Assumptions!A11 -> Market-funding gap / assets | B11: =Assumptions!B11 -> Liquidity | C11: =IF(Inputs!$D$11<=0,"n.m.",(Inputs!$D$18-Inputs!$D$16-Inputs!$D$17-Inputs!$D$12)/Inputs!$D$11) -> -0.080451184 | D11: =IF(ISNUMBER(C11),IF(Assumptions!$C$11="Higher",IF(C11>=Assumptions!$D$11,1,IF(C11>=Assumptions!$E$11,2,IF(C11>=Assumptions!$F$11,3,IF(C11>=Assumptions!$G$11,4,5)))),IF(C11<=Assumptions!$D$11,1,IF(C11<=Assumptions!$E$11,2,IF(C11<=Assumptions!$F$11,3,IF(C11<=Assumptions!$G$11,4,5))))),5) -> 3 | E11: =CHAR(64+D11) -> C | F11: =Assumptions!H11 -> 0.1 | G11: =D11*F11 -> 0.3
A12: =Assumptions!A12 -> Liquid assets / customer deposits | B12: =Assumptions!B12 -> Liquidity | C12: =IF(Inputs!$D$16<=0,"n.m.",Inputs!$D$12/Inputs!$D$16) -> 0.64721358 | D12: =IF(ISNUMBER(C12),IF(Assumptions!$C$12="Higher",IF(C12>=Assumptions!$D$12,1,IF(C12>=Assumptions!$E$12,2,IF(C12>=Assumptions!$F$12,3,IF(C12>=Assumptions!$G$12,4,5)))),IF(C12<=Assumptions!$D$12,1,IF(C12<=Assumptions!$E$12,2,IF(C12<=Assumptions!$F$12,3,IF(C12<=Assumptions!$G$12,4,5))))),5) -> 1 | E12: =CHAR(64+D12) -> A | F12: =Assumptions!H12 -> 0.1 | G12: =D12*F12 -> 0.1
A13: =Assumptions!A13 -> Cost-to-income ratio | B13: =Assumptions!B13 -> Efficiency | C13: =IF(Inputs!$D$22<=0,"n.m.",Inputs!$D$23/Inputs!$D$22) -> 0.47897833 | D13: =IF(ISNUMBER(C13),IF(Assumptions!$C$13="Higher",IF(C13>=Assumptions!$D$13,1,IF(C13>=Assumptions!$E$13,2,IF(C13>=Assumptions!$F$13,3,IF(C13>=Assumptions!$G$13,4,5)))),IF(C13<=Assumptions!$D$13,1,IF(C13<=Assumptions!$E$13,2,IF(C13<=Assumptions!$F$13,3,IF(C13<=Assumptions!$G$13,4,5))))),5) -> 2 | E13: =CHAR(64+D13) -> B | F13: =Assumptions!H13 -> 0.1 | G13: =D13*F13 -> 0.2
F14: Score | G14: =SUM(G5:G13) -> 1.3
A16: Result
A17: Weighted score (1 = strongest, 5 = weakest) | B17: =G14 -> 1.3
A18: Standalone rating | B18: =INDEX(Assumptions!$B$19:$B$30,MATCH(G14,Assumptions!$A$19:$A$30,1)) -> AA
A19: Sovereign ceiling | B19: =Inputs!C8 -> None
A20: Final rating | B20: =IF(Inputs!C8="None",B18,INDEX(Assumptions!$B$19:$B$30,MAX(MATCH(B18,Assumptions!$B$19:$B$30,0),MATCH(Inputs!C8,Assumptions!$B$19:$B$30,0)))) -> AA
A21: Indicative 1-year PD | B21: =INDEX(Assumptions!$C$19:$C$30,MATCH(B20,Assumptions!$B$19:$B$30,0)) -> 0.0003
A24: Category view
A25: Category | B25: Weight | C25: Average points | D25: Grade
A26: Capital | B26: =SUMIF($B$5:$B$13,A26,$F$5:$F$13) -> 0.2 | C26: =IFERROR(SUMIF($B$5:$B$13,A26,$G$5:$G$13)/B26,"") -> 1 | D26: =IFERROR(CHAR(64+ROUND(C26,0)),"") -> A
A27: Asset quality | B27: =SUMIF($B$5:$B$13,A27,$F$5:$F$13) -> 0.3 | C27: =IFERROR(SUMIF($B$5:$B$13,A27,$G$5:$G$13)/B27,"") -> 1 | D27: =IFERROR(CHAR(64+ROUND(C27,0)),"") -> A
A28: Profitability | B28: =SUMIF($B$5:$B$13,A28,$F$5:$F$13) -> 0.2 | C28: =IFERROR(SUMIF($B$5:$B$13,A28,$G$5:$G$13)/B28,"") -> 1 | D28: =IFERROR(CHAR(64+ROUND(C28,0)),"") -> A
A29: Liquidity | B29: =SUMIF($B$5:$B$13,A29,$F$5:$F$13) -> 0.2 | C29: =IFERROR(SUMIF($B$5:$B$13,A29,$G$5:$G$13)/B29,"") -> 2 | D29: =IFERROR(CHAR(64+ROUND(C29,0)),"") -> B
A30: Efficiency | B30: =SUMIF($B$5:$B$13,A30,$F$5:$F$13) -> 0.1 | C30: =IFERROR(SUMIF($B$5:$B$13,A30,$G$5:$G$13)/B30,"") -> 2 | D30: =IFERROR(CHAR(64+ROUND(C30,0)),"") -> B

Sheet Peer Ranking
A1: Peer ranking: every bank scored with the same model (Q4 2024)
A2: Ratios use "Peer Data" directly (overrides on "Inputs" do not apply here). Months in period are taken from Inputs!C7.
A4: Code | B4: Bank | C4: CAR | D4: Equity/RWA | E4: NPL ratio | F4: NPL/(Eq+ECL) | G4: NI/RWA | H4: PPP/RWA | I4: Mkt-fund gap | J4: Liquid/deposits | K4: CIR | L4: Pts CAR | M4: Pts Equity/RWA | N4: Pts NPL ratio | O4: Pts NPL/(Eq+ECL) | P4: Pts NI/RWA | Q4: Pts PPP/RWA | R4: Pts Mkt-fund gap | S4: Pts Liquid/deposits | T4: Pts CIR | U4: Score | V4: Rating | W4: Rank
A5: ='Peer Data'!A5 -> BBSY | B5: ='Peer Data'!B5 -> Al Baraka Bank Syria | C5: =IF('Peer Data'!N5<=0,"n.m.",'Peer Data'!M5/'Peer Data'!N5) -> 0.4914747 | D5: =IF('Peer Data'!N5<=0,"n.m.",'Peer Data'!L5/'Peer Data'!N5) -> 0.48045198 | E5: =IF('Peer Data'!F5<=0,"n.m.",'Peer Data'!G5/'Peer Data'!F5) -> 0.15113684 | F5: =IF(('Peer Data'!L5+'Peer Data'!H5)<=0,"n.m.",'Peer Data'!G5/('Peer Data'!L5+'Peer Data'!H5)) -> 0.11191032 | G5: =IF('Peer Data'!N5<=0,"n.m.",'Peer Data'!Q5*12/Inputs!$C$7/'Peer Data'!N5) -> 0.05104335 | H5: =IF('Peer Data'!N5<=0,"n.m.",('Peer Data'!O5-'Peer Data'!P5)*12/Inputs!$C$7/'Peer Data'!N5) -> 0.095495146 | I5: =IF('Peer Data'!D5<=0,"n.m.",('Peer Data'!K5-'Peer Data'!I5-'Peer Data'!J5-'Peer Data'!E5)/'Peer Data'!D5) -> -0.49702439 | J5: =IF('Peer Data'!I5<=0,"n.m.",'Peer Data'!E5/'Peer Data'!I5) -> 1.8115591 | K5: =IF('Peer Data'!O5<=0,"n.m.",'Peer Data'!P5/'Peer Data'!O5) -> 0.43642741 | L5: =IF(ISNUMBER(C5),IF(Assumptions!$C$5="Higher",IF(C5>=Assumptions!$D$5,1,IF(C5>=Assumptions!$E$5,2,IF(C5>=Assumptions!$F$5,3,IF(C5>=Assumptions!$G$5,4,5)))),IF(C5<=Assumptions!$D$5,1,IF(C5<=Assumptions!$E$5,2,IF(C5<=Assumptions!$F$5,3,IF(C5<=Assumptions!$G$5,4,5))))),5) -> 1 | M5: =IF(ISNUMBER(D5),IF(Assumptions!$C$6="Higher",IF(D5>=Assumptions!$D$6,1,IF(D5>=Assumptions!$E$6,2,IF(D5>=Assumptions!$F$6,3,IF(D5>=Assumptions!$G$6,4,5)))),IF(D5<=Assumptions!$D$6,1,IF(D5<=Assumptions!$E$6,2,IF(D5<=Assumptions!$F$6,3,IF(D5<=Assumptions!$G$6,4,5))))),5) -> 1 | N5: =IF(ISNUMBER(E5),IF(Assumptions!$C$7="Higher",IF(E5>=Assumptions!$D$7,1,IF(E5>=Assumptions!$E$7,2,IF(E5>=Assumptions!$F$7,3,IF(E5>=Assumptions!$G$7,4,5)))),IF(E5<=Assumptions!$D$7,1,IF(E5<=Assumptions!$E$7,2,IF(E5<=Assumptions!$F$7,3,IF(E5<=Assumptions!$G$7,4,5))))),5) -> 4 | O5: =IF(ISNUMBER(F5),IF(Assumptions!$C$8="Higher",IF(F5>=Assumptions!$D$8,1,IF(F5>=Assumptions!$E$8,2,IF(F5>=Assumptions!$F$8,3,IF(F5>=Assumptions!$G$8,4,5)))),IF(F5<=Assumptions!$D$8,1,IF(F5<=Assumptions!$E$8,2,IF(F5<=Assumptions!$F$8,3,IF(F5<=Assumptions!$G$8,4,5))))),5) -> 2 | P5: =IF(ISNUMBER(G5),IF(Assumptions!$C$9="Higher",IF(G5>=Assumptions!$D$9,1,IF(G5>=Assumptions!$E$9,2,IF(G5>=Assumptions!$F$9,3,IF(G5>=Assumptions!$G$9,4,5)))),IF(G5<=Assumptions!$D$9,1,IF(G5<=Assumptions!$E$9,2,IF(G5<=Assumptions!$F$9,3,IF(G5<=Assumptions!$G$9,4,5))))),5) -> 1 | Q5: =IF(ISNUMBER(H5),IF(Assumptions!$C$10="Higher",IF(H5>=Assumptions!$D$10,1,IF(H5>=Assumptions!$E$10,2,IF(H5>=Assumptions!$F$10,3,IF(H5>=Assumptions!$G$10,4,5)))),IF(H5<=Assumptions!$D$10,1,IF(H5<=Assumptions!$E$10,2,IF(H5<=Assumptions!$F$10,3,IF(H5<=Assumptions!$G$10,4,5))))),5) -> 1 | R5: =IF(ISNUMBER(I5),IF(Assumptions!$C$11="Higher",IF(I5>=Assumptions!$D$11,1,IF(I5>=Assumptions!$E$11,2,IF(I5>=Assumptions!$F$11,3,IF(I5>=Assumptions!$G$11,4,5)))),IF(I5<=Assumptions!$D$11,1,IF(I5<=Assumptions!$E$11,2,IF(I5<=Assumptions!$F$11,3,IF(I5<=Assumptions!$G$11,4,5))))),5) -> 1 | S5: =IF(ISNUMBER(J5),IF(Assumptions!$C$12="Higher",IF(J5>=Assumptions!$D$12,1,IF(J5>=Assumptions!$E$12,2,IF(J5>=Assumptions!$F$12,3,IF(J5>=Assumptions!$G$12,4,5)))),IF(J5<=Assumptions!$D$12,1,IF(J5<=Assumptions!$E$12,2,IF(J5<=Assumptions!$F$12,3,IF(J5<=Assumptions!$G$12,4,5))))),5) -> 1 | T5: =IF(ISNUMBER(K5),IF(Assumptions!$C$13="Higher",IF(K5>=Assumptions!$D$13,1,IF(K5>=Assumptions!$E$13,2,IF(K5>=Assumptions!$F$13,3,IF(K5>=Assumptions!$G$13,4,5)))),IF(K5<=Assumptions!$D$13,1,IF(K5<=Assumptions!$E$13,2,IF(K5<=Assumptions!$F$13,3,IF(K5<=Assumptions!$G$13,4,5))))),5) -> 1 | U5: =L5*Assumptions!$H$5+M5*Assumptions!$H$6+N5*Assumptions!$H$7+O5*Assumptions!$H$8+P5*Assumptions!$H$9+Q5*Assumptions!$H$10+R5*Assumptions!$H$11+S5*Assumptions!$H$12+T5*Assumptions!$H$13 -> 1.6 | V5: =INDEX(Assumptions!$B$19:$B$30,MATCH(U5,Assumptions!$A$19:$A$30,1)) -> A | W5: =RANK(U5,$U$5:$U$16,1) -> 5
A6: ='Peer Data'!A6 -> BBSF | B6: ='Peer Data'!B6 -> Banque Bemo Saudi Fransi | C6: =IF('Peer Data'!N6<=0,"n.m.",'Peer Data'!M6/'Peer Data'!N6) -> 0.20731841 | D6: =IF('Peer Data'!N6<=0,"n.m.",'Peer Data'!L6/'Peer Data'!N6) -> 0.12307654 | E6: =IF('Peer Data'!F6<=0,"n.m.",'Peer Data'!G6/'Peer Data'!F6) -> 0.33769222 | F6: =IF(('Peer Data'!L6+'Peer Data'!H6)<=0,"n.m.",'Peer Data'!G6/('Peer Data'!L6+'Peer Data'!H6)) -> 0.64407184 | G6: =IF('Peer Data'!N6<=0,"n.m.",'Peer Data'!Q6*12/Inputs!$C$7/'Peer Data'!N6) -> 0.006183816 | H6: =IF('Peer Data'!N6<=0,"n.m.",('Peer Data'!O6-'Peer Data'!P6)*12/Inputs!$C$7/'Peer Data'!N6) -> 0.081414848 | I6: =IF('Peer Data'!D6<=0,"n.m.",('Peer Data'!K6-'Peer Data'!I6-'Peer Data'!J6-'Peer Data'!E6)/'Peer Data'!D6) -> -0.71652129 | J6: =IF('Peer Data'!I6<=0,"n.m.",'Peer Data'!E6/'Peer Data'!I6) -> 0.79748481 | K6: =IF('Peer Data'!O6<=0,"n.m.",'Peer Data'!P6/'Peer Data'!O6) -> 0.37469672 | L6: =IF(ISNUMBER(C6),IF(Assumptions!$C$5="Higher",IF(C6>=Assumptions!$D$5,1,IF(C6>=Assumptions!$E$5,2,IF(C6>=Assumptions!$F$5,3,IF(C6>=Assumptions!$G$5,4,5)))),IF(C6<=Assumptions!$D$5,1,IF(C6<=Assumptions!$E$5,2,IF(C6<=Assumptions!$F$5,3,IF(C6<=Assumptions!$G$5,4,5))))),5) -> 1 | M6: =IF(ISNUMBER(D6),IF(Assumptions!$C$6="Higher",IF(D6>=Assumptions!$D$6,1,IF(D6>=Assumptions!$E$6,2,IF(D6>=Assumptions!$F$6,3,IF(D6>=Assumptions!$G$6,4,5)))),IF(D6<=Assumptions!$D$6,1,IF(D6<=Assumptions!$E$6,2,IF(D6<=Assumptions!$F$6,3,IF(D6<=Assumptions!$G$6,4,5))))),5) -> 2 | N6: =IF(ISNUMBER(E6),IF(Assumptions!$C$7="Higher",IF(E6>=Assumptions!$D$7,1,IF(E6>=Assumptions!$E$7,2,IF(E6>=Assumptions!$F$7,3,IF(E6>=Assumptions!$G$7,4,5)))),IF(E6<=Assumptions!$D$7,1,IF(E6<=Assumptions!$E$7,2,IF(E6<=Assumptions!$F$7,3,IF(E6<=Assumptions!$G$7,4,5))))),5) -> 5 | O6: =IF(ISNUMBER(F6),IF(Assumptions!$C$8="Higher",IF(F6>=Assumptions!$D$8,1,IF(F6>=Assumptions!$E$8,2,IF(F6>=Assumptions!$F$8,3,IF(F6>=Assumptions!$G$8,4,5)))),IF(F6<=Assumptions!$D$8,1,IF(F6<=Assumptions!$E$8,2,IF(F6<=Assumptions!$F$8,3,IF(F6<=Assumptions!$G$8,4,5))))),5) -> 4 | P6: =IF(ISNUMBER(G6),IF(Assumptions!$C$9="Higher",IF(G6>=Assumptions!$D$9,1,IF(G6>=Assumptions!$E$9,2,IF(G6>=Assumptions!$F$9,3,IF(G6>=Assumptions!$G$9,4,5)))),IF(G6<=Assumptions!$D$9,1,IF(G6<=Assumptions!$E$9,2,IF(G6<=Assumptions!$F$9,3,IF(G6<=Assumptions!$G$9,4,5))))),5) -> 4 | Q6: =IF(ISNUMBER(H6),IF(Assumptions!$C$10="Higher",IF(H6>=Assumptions!$D$10,1,IF(H6>=Assumptions!$E$10,2,IF(H6>=Assumptions!$F$10,3,IF(H6>=Assumptions!$G$10,4,5)))),IF(H6<=Assumptions!$D$10,1,IF(H6<=Assumptions!$E$10,2,IF(H6<=Assumptions!$F$10,3,IF(H6<=Assumptions!$G$10,4,5))))),5) -> 1 | R6: =IF(ISNUMBER(I6),IF(Assumptions!$C$11="Higher",IF(I6>=Assumptions!$D$11,1,IF(I6>=Assumptions!$E$11,2,IF(I6>=Assumptions!$F$11,3,IF(I6>=Assumptions!$G$11,4,5)))),IF(I6<=Assumptions!$D$11,1,IF(I6<=Assumptions!$E$11,2,IF(I6<=Assumptions!$F$11,3,IF(I6<=Assumptions!$G$11,4,5))))),5) -> 1 | S6: =IF(ISNUMBER(J6),IF(Assumptions!$C$12="Higher",IF(J6>=Assumptions!$D$12,1,IF(J6>=Assumptions!$E$12,2,IF(J6>=Assumptions!$F$12,3,IF(J6>=Assumptions!$G$12,4,5)))),IF(J6<=Assumptions!$D$12,1,IF(J6<=Assumptions!$E$12,2,IF(J6<=Assumptions!$F$12,3,IF(J6<=Assumptions!$G$12,4,5))))),5) -> 1 | T6: =IF(ISNUMBER(K6),IF(Assumptions!$C$13="Higher",IF(K6>=Assumptions!$D$13,1,IF(K6>=Assumptions!$E$13,2,IF(K6>=Assumptions!$F$13,3,IF(K6>=Assumptions!$G$13,4,5)))),IF(K6<=Assumptions!$D$13,1,IF(K6<=Assumptions!$E$13,2,IF(K6<=Assumptions!$F$13,3,IF(K6<=Assumptions!$G$13,4,5))))),5) -> 1 | U6: =L6*Assumptions!$H$5+M6*Assumptions!$H$6+N6*Assumptions!$H$7+O6*Assumptions!$H$8+P6*Assumptions!$H$9+Q6*Assumptions!$H$10+R6*Assumptions!$H$11+S6*Assumptions!$H$12+T6*Assumptions!$H$13 -> 2.45 | V6: =INDEX(Assumptions!$B$19:$B$30,MATCH(U6,Assumptions!$A$19:$A$30,1)) -> BBB- | W6: =RANK(U6,$U$5:$U$16,1) -> 8
A7: ='Peer Data'!A7 -> QNBS | B7: ='Peer Data'!B7 -> QNB Syria | C7: =IF('Peer Data'!N7<=0,"n.m.",'Peer Data'!M7/'Peer Data'!N7) -> 2.0642407 | D7: =IF('Peer Data'!N7<=0,"n.m.",'Peer Data'!L7/'Peer Data'!N7) -> 2.0652651 | E7: =IF('Peer Data'!F7<=0,"n.m.",'Peer Data'!G7/'Peer Data'!F7) -> 0 | F7: =IF(('Peer Data'!L7+'Peer Data'!H7)<=0,"n.m.",'Peer Data'!G7/('Peer Data'!L7+'Peer Data'!H7)) -> 0 | G7: =IF('Peer Data'!N7<=0,"n.m.",'Peer Data'!Q7*12/Inputs!$C$7/'Peer Data'!N7) -> 0.056253515 | H7: =IF('Peer Data'!N7<=0,"n.m.",('Peer Data'!O7-'Peer Data'!P7)*12/Inputs!$C$7/'Peer Data'!N7) -> 0.060241489 | I7: =IF('Peer Data'!D7<=0,"n.m.",('Peer Data'!K7-'Peer Data'!I7-'Peer Data'!J7-'Peer Data'!E7)/'Peer Data'!D7) -> -0.080451184 | J7: =IF('Peer Data'!I7<=0,"n.m.",'Peer Data'!E7/'Peer Data'!I7) -> 0.64721358 | K7: =IF('Peer Data'!O7<=0,"n.m.",'Peer Data'!P7/'Peer Data'!O7) -> 0.47897833 | L7: =IF(ISNUMBER(C7),IF(Assumptions!$C$5="Higher",IF(C7>=Assumptions!$D$5,1,IF(C7>=Assumptions!$E$5,2,IF(C7>=Assumptions!$F$5,3,IF(C7>=Assumptions!$G$5,4,5)))),IF(C7<=Assumptions!$D$5,1,IF(C7<=Assumptions!$E$5,2,IF(C7<=Assumptions!$F$5,3,IF(C7<=Assumptions!$G$5,4,5))))),5) -> 1 | M7: =IF(ISNUMBER(D7),IF(Assumptions!$C$6="Higher",IF(D7>=Assumptions!$D$6,1,IF(D7>=Assumptions!$E$6,2,IF(D7>=Assumptions!$F$6,3,IF(D7>=Assumptions!$G$6,4,5)))),IF(D7<=Assumptions!$D$6,1,IF(D7<=Assumptions!$E$6,2,IF(D7<=Assumptions!$F$6,3,IF(D7<=Assumptions!$G$6,4,5))))),5) -> 1 | N7: =IF(ISNUMBER(E7),IF(Assumptions!$C$7="Higher",IF(E7>=Assumptions!$D$7,1,IF(E7>=Assumptions!$E$7,2,IF(E7>=Assumptions!$F$7,3,IF(E7>=Assumptions!$G$7,4,5)))),IF(E7<=Assumptions!$D$7,1,IF(E7<=Assumptions!$E$7,2,IF(E7<=Assumptions!$F$7,3,IF(E7<=Assumptions!$G$7,4,5))))),5) -> 1 | O7: =IF(ISNUMBER(F7),IF(Assumptions!$C$8="Higher",IF(F7>=Assumptions!$D$8,1,IF(F7>=Assumptions!$E$8,2,IF(F7>=Assumptions!$F$8,3,IF(F7>=Assumptions!$G$8,4,5)))),IF(F7<=Assumptions!$D$8,1,IF(F7<=Assumptions!$E$8,2,IF(F7<=Assumptions!$F$8,3,IF(F7<=Assumptions!$G$8,4,5))))),5) -> 1 | P7: =IF(ISNUMBER(G7),IF(Assumptions!$C$9="Higher",IF(G7>=Assumptions!$D$9,1,IF(G7>=Assumptions!$E$9,2,IF(G7>=Assumptions!$F$9,3,IF(G7>=Assumptions!$G$9,4,5)))),IF(G7<=Assumptions!$D$9,1,IF(G7<=Assumptions!$E$9,2,IF(G7<=Assumptions!$F$9,3,IF(G7<=Assumptions!$G$9,4,5))))),5) -> 1 | Q7: =IF(ISNUMBER(H7),IF(Assumptions!$C$10="Higher",IF(H7>=Assumptions!$D$10,1,IF(H7>=Assumptions!$E$10,2,IF(H7>=Assumptions!$F$10,3,IF(H7>=Assumptions!$G$10,4,5)))),IF(H7<=Assumptions!$D$10,1,IF(H7<=Assumptions!$E$10,2,IF(H7<=Assumptions!$F$10,3,IF(H7<=Assumptions!$G$10,4,5))))),5) -> 1 | R7: =IF(ISNUMBER(I7),IF(Assumptions!$C$11="Higher",IF(I7>=Assumptions!$D$11,1,IF(I7>=Assumptions!$E$11,2,IF(I7>=Assumptions!$F$11,3,IF(I7>=Assumptions!$G$11,4,5)))),IF(I7<=Assumptions!$D$11,1,IF(I7<=Assumptions!$E$11,2,IF(I7<=Assumptions!$F$11,3,IF(I7<=Assumptions!$G$11,4,5))))),5) -> 3 | S7: =IF(ISNUMBER(J7),IF(Assumptions!$C$12="Higher",IF(J7>=Assumptions!$D$12,1,IF(J7>=Assumptions!$E$12,2,IF(J7>=Assumptions!$F$12,3,IF(J7>=Assumptions!$G$12,4,5)))),IF(J7<=Assumptions!$D$12,1,IF(J7<=Assumptions!$E$12,2,IF(J7<=Assumptions!$F$12,3,IF(J7<=Assumptions!$G$12,4,5))))),5) -> 1 | T7: =IF(ISNUMBER(K7),IF(Assumptions!$C$13="Higher",IF(K7>=Assumptions!$D$13,1,IF(K7>=Assumptions!$E$13,2,IF(K7>=Assumptions!$F$13,3,IF(K7>=Assumptions!$G$13,4,5)))),IF(K7<=Assumptions!$D$13,1,IF(K7<=Assumptions!$E$13,2,IF(K7<=Assumptions!$F$13,3,IF(K7<=Assumptions!$G$13,4,5))))),5) -> 2 | U7: =L7*Assumptions!$H$5+M7*Assumptions!$H$6+N7*Assumptions!$H$7+O7*Assumptions!$H$8+P7*Assumptions!$H$9+Q7*Assumptions!$H$10+R7*Assumptions!$H$11+S7*Assumptions!$H$12+T7*Assumptions!$H$13 -> 1.3 | V7: =INDEX(Assumptions!$B$19:$B$30,MATCH(U7,Assumptions!$A$19:$A$30,1)) -> AA | W7: =RANK(U7,$U$5:$U$16,1) -> 2
A8: ='Peer Data'!A8 -> BSO | B8: ='Peer Data'!B8 -> Bank of Syria and Overseas | C8: =IF('Peer Data'!N8<=0,"n.m.",'Peer Data'!M8/'Peer Data'!N8) -> 0.3804487 | D8: =IF('Peer Data'!N8<=0,"n.m.",'Peer Data'!L8/'Peer Data'!N8) -> 0.37977005 | E8: =IF('Peer Data'!F8<=0,"n.m.",'Peer Data'!G8/'Peer Data'!F8) -> 0.032015739 | F8: =IF(('Peer Data'!L8+'Peer Data'!H8)<=0,"n.m.",'Peer Data'!G8/('Peer Data'!L8+'Peer Data'!H8)) -> 0.0035358684 | G8: =IF('Peer Data'!N8<=0,"n.m.",'Peer Data'!Q8*12/Inputs!$C$7/'Peer Data'!N8) -> 0.025238686 | H8: =IF('Peer Data'!N8<=0,"n.m.",('Peer Data'!O8-'Peer Data'!P8)*12/Inputs!$C$7/'Peer Data'!N8) -> 0.033670855 | I8: =IF('Peer Data'!D8<=0,"n.m.",('Peer Data'!K8-'Peer Data'!I8-'Peer Data'!J8-'Peer Data'!E8)/'Peer Data'!D8) -> -0.65203091 | J8: =IF('Peer Data'!I8<=0,"n.m.",'Peer Data'!E8/'Peer Data'!I8) -> 1.0431225 | K8: =IF('Peer Data'!O8<=0,"n.m.",'Peer Data'!P8/'Peer Data'!O8) -> 0.52140461 | L8: =IF(ISNUMBER(C8),IF(Assumptions!$C$5="Higher",IF(C8>=Assumptions!$D$5,1,IF(C8>=Assumptions!$E$5,2,IF(C8>=Assumptions!$F$5,3,IF(C8>=Assumptions!$G$5,4,5)))),IF(C8<=Assumptions!$D$5,1,IF(C8<=Assumptions!$E$5,2,IF(C8<=Assumptions!$F$5,3,IF(C8<=Assumptions!$G$5,4,5))))),5) -> 1 | M8: =IF(ISNUMBER(D8),IF(Assumptions!$C$6="Higher",IF(D8>=Assumptions!$D$6,1,IF(D8>=Assumptions!$E$6,2,IF(D8>=Assumptions!$F$6,3,IF(D8>=Assumptions!$G$6,4,5)))),IF(D8<=Assumptions!$D$6,1,IF(D8<=Assumptions!$E$6,2,IF(D8<=Assumptions!$F$6,3,IF(D8<=Assumptions!$G$6,4,5))))),5) -> 1 | N8: =IF(ISNUMBER(E8),IF(Assumptions!$C$7="Higher",IF(E8>=Assumptions!$D$7,1,IF(E8>=Assumptions!$E$7,2,IF(E8>=Assumptions!$F$7,3,IF(E8>=Assumptions!$G$7,4,5)))),IF(E8<=Assumptions!$D$7,1,IF(E8<=Assumptions!$E$7,2,IF(E8<=Assumptions!$F$7,3,IF(E8<=Assumptions!$G$7,4,5))))),5) -> 2 | O8: =IF(ISNUMBER(F8),IF(Assumptions!$C$8="Higher",IF(F8>=Assumptions!$D$8,1,IF(F8>=Assumptions!$E$8,2,IF(F8>=Assumptions!$F$8,3,IF(F8>=Assumptions!$G$8,4,5)))),IF(F8<=Assumptions!$D$8,1,IF(F8<=Assumptions!$E$8,2,IF(F8<=Assumptions!$F$8,3,IF(F8<=Assumptions!$G$8,4,5))))),5) -> 1 | P8: =IF(ISNUMBER(G8),IF(Assumptions!$C$9="Higher",IF(G8>=Assumptions!$D$9,1,IF(G8>=Assumptions!$E$9,2,IF(G8>=Assumptions!$F$9,3,IF(G8>=Assumptions!$G$9,4,5)))),IF(G8<=Assumptions!$D$9,1,IF(G8<=Assumptions!$E$9,2,IF(G8<=Assumptions!$F$9,3,IF(G8<=Assumptions!$G$9,4,5))))),5) -> 1 | Q8: =IF(ISNUMBER(H8),IF(Assumptions!$C$10="Higher",IF(H8>=Assumptions!$D$10,1,IF(H8>=Assumptions!$E$10,2,IF(H8>=Assumptions!$F$10,3,IF(H8>=Assumptions!$G$10,4,5)))),IF(H8<=Assumptions!$D$10,1,IF(H8<=Assumptions!$E$10,2,IF(H8<=Assumptions!$F$10,3,IF(H8<=Assumptions!$G$10,4,5))))),5) -> 2 | R8: =IF(ISNUMBER(I8),IF(Assumptions!$C$11="Higher",IF(I8>=Assumptions!$D$11,1,IF(I8>=Assumptions!$E$11,2,IF(I8>=Assumptions!$F$11,3,IF(I8>=Assumptions!$G$11,4,5)))),IF(I8<=Assumptions!$D$11,1,IF(I8<=Assumptions!$E$11,2,IF(I8<=Assumptions!$F$11,3,IF(I8<=Assumptions!$G$11,4,5))))),5) -> 1 | S8: =IF(ISNUMBER(J8),IF(Assumptions!$C$12="Higher",IF(J8>=Assumptions!$D$12,1,IF(J8>=Assumptions!$E$12,2,IF(J8>=Assumptions!$F$12,3,IF(J8>=Assumptions!$G$12,4,5)))),IF(J8<=Assumptions!$D$12,1,IF(J8<=Assumptions!$E$12,2,IF(J8<=Assumptions!$F$12,3,IF(J8<=Assumptions!$G$12,4,5))))),5) -> 1 | T8: =IF(ISNUMBER(K8),IF(Assumptions!$C$13="Higher",IF(K8>=Assumptions!$D$13,1,IF(K8>=Assumptions!$E$13,2,IF(K8>=Assumptions!$F$13,3,IF(K8>=Assumptions!$G$13,4,5)))),IF(K8<=Assumptions!$D$13,1,IF(K8<=Assumptions!$E$13,2,IF(K8<=Assumptions!$F$13,3,IF(K8<=Assumptions!$G$13,4,5))))),5) -> 2 | U8: =L8*Assumptions!$H$5+M8*Assumptions!$H$6+N8*Assumptions!$H$7+O8*Assumptions!$H$8+P8*Assumptions!$H$9+Q8*Assumptions!$H$10+R8*Assumptions!$H$11+S8*Assumptions!$H$12+T8*Assumptions!$H$13 -> 1.35 | V8: =INDEX(Assumptions!$B$19:$B$30,MATCH(U8,Assumptions!$A$19:$A$30,1)) -> AA | W8: =RANK(U8,$U$5:$U$16,1) -> 3
A9: ='Peer Data'!A9 -> IBTF | B9: ='Peer Data'!B9 -> Intl. Bank for Trade & Finance | C9: =IF('Peer Data'!N9<=0,"n.m.",'Peer Data'!M9/'Peer Data'!N9) -> 0.58865483 | D9: =IF('Peer Data'!N9<=0,"n.m.",'Peer Data'!L9/'Peer Data'!N9) -> 0.58272182 | E9: =IF('Peer Data'!F9<=0,"n.m.",'Peer Data'!G9/'Peer Data'!F9) -> 0.0061688684 | F9: =IF(('Peer Data'!L9+'Peer Data'!H9)<=0,"n.m.",'Peer Data'!G9/('Peer Data'!L9+'Peer Data'!H9)) -> 0.0011736007 | G9: =IF('Peer Data'!N9<=0,"n.m.",'Peer Data'!Q9*12/Inputs!$C$7/'Peer Data'!N9) -> 0.032357824 | H9: =IF('Peer Data'!N9<=0,"n.m.",('Peer Data'!O9-'Peer Data'!P9)*12/Inputs!$C$7/'Peer Data'!N9) -> 0.039200524 | I9: =IF('Peer Data'!D9<=0,"n.m.",('Peer Data'!K9-'Peer Data'!I9-'Peer Data'!J9-'Peer Data'!E9)/'Peer Data'!D9) -> -0.57175288 | J9: =IF('Peer Data'!I9<=0,"n.m.",'Peer Data'!E9/'Peer Data'!I9) -> 1.1133014 | K9: =IF('Peer Data'!O9<=0,"n.m.",'Peer Data'!P9/'Peer Data'!O9) -> 0.51181617 | L9: =IF(ISNUMBER(C9),IF(Assumptions!$C$5="Higher",IF(C9>=Assumptions!$D$5,1,IF(C9>=Assumptions!$E$5,2,IF(C9>=Assumptions!$F$5,3,IF(C9>=Assumptions!$G$5,4,5)))),IF(C9<=Assumptions!$D$5,1,IF(C9<=Assumptions!$E$5,2,IF(C9<=Assumptions!$F$5,3,IF(C9<=Assumptions!$G$5,4,5))))),5) -> 1 | M9: =IF(ISNUMBER(D9),IF(Assumptions!$C$6="Higher",IF(D9>=Assumptions!$D$6,1,IF(D9>=Assumptions!$E$6,2,IF(D9>=Assumptions!$F$6,3,IF(D9>=Assumptions!$G$6,4,5)))),IF(D9<=Assumptions!$D$6,1,IF(D9<=Assumptions!$E$6,2,IF(D9<=Assumptions!$F$6,3,IF(D9<=Assumptions!$G$6,4,5))))),5) -> 1 | N9: =IF(ISNUMBER(E9),IF(Assumptions!$C$7="Higher",IF(E9>=Assumptions!$D$7,1,IF(E9>=Assumptions!$E$7,2,IF(E9>=Assumptions!$F$7,3,IF(E9>=Assumptions!$G$7,4,5)))),IF(E9<=Assumptions!$D$7,1,IF(E9<=Assumptions!$E$7,2,IF(E9<=Assumptions!$F$7,3,IF(E9<=Assumptions!$G$7,4,5))))),5) -> 1 | O9: =IF(ISNUMBER(F9),IF(Assumptions!$C$8="Higher",IF(F9>=Assumptions!$D$8,1,IF(F9>=Assumptions!$E$8,2,IF(F9>=Assumptions!$F$8,3,IF(F9>=Assumptions!$G$8,4,5)))),IF(F9<=Assumptions!$D$8,1,IF(F9<=Assumptions!$E$8,2,IF(F9<=Assumptions!$F$8,3,IF(F9<=Assumptions!$G$8,4,5))))),5) -> 1 | P9: =IF(ISNUMBER(G9),IF(Assumptions!$C$9="Higher",IF(G9>=Assumptions!$D$9,1,IF(G9>=Assumptions!$E$9,2,IF(G9>=Assumptions!$F$9,3,IF(G9>=Assumptions!$G$9,4,5)))),IF(G9<=Assumptions!$D$9,1,IF(G9<=Assumptions!$E$9,2,IF(G9<=Assumptions!$F$9,3,IF(G9<=Assumptions!$G$9,4,5))))),5) -> 1 | Q9: =IF(ISNUMBER(H9),IF(Assumptions!$C$10="Higher",IF(H9>=Assumptions!$D$10,1,IF(H9>=Assumptions!$E$10,2,IF(H9>=Assumptions!$F$10,3,IF(H9>=Assumptions!$G$10,4,5)))),IF(H9<=Assumptions!$D$10,1,IF(H9<=Assumptions!$E$10,2,IF(H9<=Assumptions!$F$10,3,IF(H9<=Assumptions!$G$10,4,5))))),5) -> 2 | R9: =IF(ISNUMBER(I9),IF(Assumptions!$C$11="Higher",IF(I9>=Assumptions!$D$11,1,IF(I9>=Assumptions!$E$11,2,IF(I9>=Assumptions!$F$11,3,IF(I9>=Assumptions!$G$11,4,5)))),IF(I9<=Assumptions!$D$11,1,IF(I9<=Assumptions!$E$11,2,IF(I9<=Assumptions!$F$11,3,IF(I9<=Assumptions!$G$11,4,5))))),5) -> 1 | S9: =IF(ISNUMBER(J9),IF(Assumptions!$C$12="Higher",IF(J9>=Assumptions!$D$12,1,IF(J9>=Assumptions!$E$12,2,IF(J9>=Assumptions!$F$12,3,IF(J9>=Assumptions!$G$12,4,5)))),IF(J9<=Assumptions!$D$12,1,IF(J9<=Assumptions!$E$12,2,IF(J9<=Assumptions!$F$12,3,IF(J9<=Assumptions!$G$12,4,5))))),5) -> 1 | T9: =IF(ISNUMBER(K9),IF(Assumptions!$C$13="Higher",IF(K9>=Assumptions!$D$13,1,IF(K9>=Assumptions!$E$13,2,IF(K9>=Assumptions!$F$13,3,IF(K9>=Assumptions!$G$13,4,5)))),IF(K9<=Assumptions!$D$13,1,IF(K9<=Assumptions!$E$13,2,IF(K9<=Assumptions!$F$13,3,IF(K9<=Assumptions!$G$13,4,5))))),5) -> 2 | U9: =L9*Assumptions!$H$5+M9*Assumptions!$H$6+N9*Assumptions!$H$7+O9*Assumptions!$H$8+P9*Assumptions!$H$9+Q9*Assumptions!$H$10+R9*Assumptions!$H$11+S9*Assumptions!$H$12+T9*Assumptions!$H$13 -> 1.2 | V9: =INDEX(Assumptions!$B$19:$B$30,MATCH(U9,Assumptions!$A$19:$A$30,1)) -> AA | W9: =RANK(U9,$U$5:$U$16,1) -> 1
A10: ='Peer Data'!A10 -> ATB | B10: ='Peer Data'!B10 -> Al Ahli Bank | C10: =IF('Peer Data'!N10<=0,"n.m.",'Peer Data'!M10/'Peer Data'!N10) -> 0.35258099 | D10: =IF('Peer Data'!N10<=0,"n.m.",'Peer Data'!L10/'Peer Data'!N10) -> 0.49735745 | E10: =IF('Peer Data'!F10<=0,"n.m.",'Peer Data'!G10/'Peer Data'!F10) -> 0.031806486 | F10: =IF(('Peer Data'!L10+'Peer Data'!H10)<=0,"n.m.",'Peer Data'!G10/('Peer Data'!L10+'Peer Data'!H10)) -> 0.010597164 | G10: =IF('Peer Data'!N10<=0,"n.m.",'Peer Data'!Q10*12/Inputs!$C$7/'Peer Data'!N10) -> 0.011703557 | H10: =IF('Peer Data'!N10<=0,"n.m.",('Peer Data'!O10-'Peer Data'!P10)*12/Inputs!$C$7/'Peer Data'!N10) -> 0.029951514 | I10: =IF('Peer Data'!D10<=0,"n.m.",('Peer Data'!K10-'Peer Data'!I10-'Peer Data'!J10-'Peer Data'!E10)/'Peer Data'!D10) -> -0.39141471 | J10: =IF('Peer Data'!I10<=0,"n.m.",'Peer Data'!E10/'Peer Data'!I10) -> 1.3938773 | K10: =IF('Peer Data'!O10<=0,"n.m.",'Peer Data'!P10/'Peer Data'!O10) -> 0.59398582 | L10: =IF(ISNUMBER(C10),IF(Assumptions!$C$5="Higher",IF(C10>=Assumptions!$D$5,1,IF(C10>=Assumptions!$E$5,2,IF(C10>=Assumptions!$F$5,3,IF(C10>=Assumptions!$G$5,4,5)))),IF(C10<=Assumptions!$D$5,1,IF(C10<=Assumptions!$E$5,2,IF(C10<=Assumptions!$F$5,3,IF(C10<=Assumptions!$G$5,4,5))))),5) -> 1 | M10: =IF(ISNUMBER(D10),IF(Assumptions!$C$6="Higher",IF(D10>=Assumptions!$D$6,1,IF(D10>=Assumptions!$E$6,2,IF(D10>=Assumptions!$F$6,3,IF(D10>=Assumptions!$G$6,4,5)))),IF(D10<=Assumptions!$D$6,1,IF(D10<=Assumptions!$E$6,2,IF(D10<=Assumptions!$F$6,3,IF(D10<=Assumptions!$G$6,4,5))))),5) -> 1 | N10: =IF(ISNUMBER(E10),IF(Assumptions!$C$7="Higher",IF(E10>=Assumptions!$D$7,1,IF(E10>=Assumptions!$E$7,2,IF(E10>=Assumptions!$F$7,3,IF(E10>=Assumptions!$G$7,4,5)))),IF(E10<=Assumptions!$D$7,1,IF(E10<=Assumptions!$E$7,2,IF(E10<=Assumptions!$F$7,3,IF(E10<=Assumptions!$G$7,4,5))))),5) -> 2 | O10: =IF(ISNUMBER(F10),IF(Assumptions!$C$8="Higher",IF(F10>=Assumptions!$D$8,1,IF(F10>=Assumptions!$E$8,2,IF(F10>=Assumptions!$F$8,3,IF(F10>=Assumptions!$G$8,4,5)))),IF(F10<=Assumptions!$D$8,1,IF(F10<=Assumptions!$E$8,2,IF(F10<=Assumptions!$F$8,3,IF(F10<=Assumptions!$G$8,4,5))))),5) -> 1 | P10: =IF(ISNUMBER(G10),IF(Assumptions!$C$9="Higher",IF(G10>=Assumptions!$D$9,1,IF(G10>=Assumptions!$E$9,2,IF(G10>=Assumptions!$F$9,3,IF(G10>=Assumptions!$G$9,4,5)))),IF(G10<=Assumptions!$D$9,1,IF(G10<=Assumptions!$E$9,2,IF(G10<=Assumptions!$F$9,3,IF(G10<=Assumptions!$G$9,4,5))))),5) -> 3 | Q10: =IF(ISNUMBER(H10),IF(Assumptions!$C$10="Higher",IF(H10>=Assumptions!$D$10,1,IF(H10>=Assumptions!$E$10,2,IF(H10>=Assumptions!$F$10,3,IF(H10>=Assumptions!$G$10,4,5)))),IF(H10<=Assumptions!$D$10,1,IF(H10<=Assumptions!$E$10,2,IF(H10<=Assumptions!$F$10,3,IF(H10<=Assumptions!$G$10,4,5))))),5) -> 2 | R10: =IF(ISNUMBER(I10),IF(Assumptions!$C$11="Higher",IF(I10>=Assumptions!$D$11,1,IF(I10>=Assumptions!$E$11,2,IF(I10>=Assumptions!$F$11,3,IF(I10>=Assumptions!$G$11,4,5)))),IF(I10<=Assumptions!$D$11,1,IF(I10<=Assumptions!$E$11,2,IF(I10<=Assumptions!$F$11,3,IF(I10<=Assumptions!$G$11,4,5))))),5) -> 1 | S10: =IF(ISNUMBER(J10),IF(Assumptions!$C$12="Higher",IF(J10>=Assumptions!$D$12,1,IF(J10>=Assumptions!$E$12,2,IF(J10>=Assumptions!$F$12,3,IF(J10>=Assumptions!$G$12,4,5)))),IF(J10<=Assumptions!$D$12,1,IF(J10<=Assumptions!$E$12,2,IF(J10<=Assumptions!$F$12,3,IF(J10<=Assumptions!$G$12,4,5))))),5) -> 1 | T10: =IF(ISNUMBER(K10),IF(Assumptions!$C$13="Higher",IF(K10>=Assumptions!$D$13,1,IF(K10>=Assumptions!$E$13,2,IF(K10>=Assumptions!$F$13,3,IF(K10>=Assumptions!$G$13,4,5)))),IF(K10<=Assumptions!$D$13,1,IF(K10<=Assumptions!$E$13,2,IF(K10<=Assumptions!$F$13,3,IF(K10<=Assumptions!$G$13,4,5))))),5) -> 3 | U10: =L10*Assumptions!$H$5+M10*Assumptions!$H$6+N10*Assumptions!$H$7+O10*Assumptions!$H$8+P10*Assumptions!$H$9+Q10*Assumptions!$H$10+R10*Assumptions!$H$11+S10*Assumptions!$H$12+T10*Assumptions!$H$13 -> 1.65 | V10: =INDEX(Assumptions!$B$19:$B$30,MATCH(U10,Assumptions!$A$19:$A$30,1)) -> A | W10: =RANK(U10,$U$5:$U$16,1) -> 6
A11: ='Peer Data'!A11 -> FSBS | B11: ='Peer Data'!B11 -> Fransabank Syria | C11: =IF('Peer Data'!N11<=0,"n.m.",'Peer Data'!M11/'Peer Data'!N11) -> 0.54305376 | D11: =IF('Peer Data'!N11<=0,"n.m.",'Peer Data'!L11/'Peer Data'!N11) -> 0.54963073 | E11: =IF('Peer Data'!F11<=0,"n.m.",'Peer Data'!G11/'Peer Data'!F11) -> 0.49769532 | F11: =IF(('Peer Data'!L11+'Peer Data'!H11)<=0,"n.m.",'Peer Data'!G11/('Peer Data'!L11+'Peer Data'!H11)) -> 0.26242164 | G11: =IF('Peer Data'!N11<=0,"n.m.",'Peer Data'!Q11*12/Inputs!$C$7/'Peer Data'!N11) -> -0.025217667 | H11: =IF('Peer Data'!N11<=0,"n.m.",('Peer Data'!O11-'Peer Data'!P11)*12/Inputs!$C$7/'Peer Data'!N11) -> -0.015900106 | I11: =IF('Peer Data'!D11<=0,"n.m.",('Peer Data'!K11-'Peer Data'!I11-'Peer Data'!J11-'Peer Data'!E11)/'Peer Data'!D11) -> -0.61956049 | J11: =IF('Peer Data'!I11<=0,"n.m.",'Peer Data'!E11/'Peer Data'!I11) -> 1.7786686 | K11: =IF('Peer Data'!O11<=0,"n.m.",'Peer Data'!P11/'Peer Data'!O11) -> 1.6102743 | L11: =IF(ISNUMBER(C11),IF(Assumptions!$C$5="Higher",IF(C11>=Assumptions!$D$5,1,IF(C11>=Assumptions!$E$5,2,IF(C11>=Assumptions!$F$5,3,IF(C11>=Assumptions!$G$5,4,5)))),IF(C11<=Assumptions!$D$5,1,IF(C11<=Assumptions!$E$5,2,IF(C11<=Assumptions!$F$5,3,IF(C11<=Assumptions!$G$5,4,5))))),5) -> 1 | M11: =IF(ISNUMBER(D11),IF(Assumptions!$C$6="Higher",IF(D11>=Assumptions!$D$6,1,IF(D11>=Assumptions!$E$6,2,IF(D11>=Assumptions!$F$6,3,IF(D11>=Assumptions!$G$6,4,5)))),IF(D11<=Assumptions!$D$6,1,IF(D11<=Assumptions!$E$6,2,IF(D11<=Assumptions!$F$6,3,IF(D11<=Assumptions!$G$6,4,5))))),5) -> 1 | N11: =IF(ISNUMBER(E11),IF(Assumptions!$C$7="Higher",IF(E11>=Assumptions!$D$7,1,IF(E11>=Assumptions!$E$7,2,IF(E11>=Assumptions!$F$7,3,IF(E11>=Assumptions!$G$7,4,5)))),IF(E11<=Assumptions!$D$7,1,IF(E11<=Assumptions!$E$7,2,IF(E11<=Assumptions!$F$7,3,IF(E11<=Assumptions!$G$7,4,5))))),5) -> 5 | O11: =IF(ISNUMBER(F11),IF(Assumptions!$C$8="Higher",IF(F11>=Assumptions!$D$8,1,IF(F11>=Assumptions!$E$8,2,IF(F11>=Assumptions!$F$8,3,IF(F11>=Assumptions!$G$8,4,5)))),IF(F11<=Assumptions!$D$8,1,IF(F11<=Assumptions!$E$8,2,IF(F11<=Assumptions!$F$8,3,IF(F11<=Assumptions!$G$8,4,5))))),5) -> 3 | P11: =IF(ISNUMBER(G11),IF(Assumptions!$C$9="Higher",IF(G11>=Assumptions!$D$9,1,IF(G11>=Assumptions!$E$9,2,IF(G11>=Assumptions!$F$9,3,IF(G11>=Assumptions!$G$9,4,5)))),IF(G11<=Assumptions!$D$9,1,IF(G11<=Assumptions!$E$9,2,IF(G11<=Assumptions!$F$9,3,IF(G11<=Assumptions!$G$9,4,5))))),5) -> 5 | Q11: =IF(ISNUMBER(H11),IF(Assumptions!$C$10="Higher",IF(H11>=Assumptions!$D$10,1,IF(H11>=Assumptions!$E$10,2,IF(H11>=Assumptions!$F$10,3,IF(H11>=Assumptions!$G$10,4,5)))),IF(H11<=Assumptions!$D$10,1,IF(H11<=Assumptions!$E$10,2,IF(H11<=Assumptions!$F$10,3,IF(H11<=Assumptions!$G$10,4,5))))),5) -> 5 | R11: =IF(ISNUMBER(I11),IF(Assumptions!$C$11="Higher",IF(I11>=Assumptions!$D$11,1,IF(I11>=Assumptions!$E$11,2,IF(I11>=Assumptions!$F$11,3,IF(I11>=Assumptions!$G$11,4,5)))),IF(I11<=Assumptions!$D$11,1,IF(I11<=Assumptions!$E$11,2,IF(I11<=Assumptions!$F$11,3,IF(I11<=Assumptions!$G$11,4,5))))),5) -> 1 | S11: =IF(ISNUMBER(J11),IF(Assumptions!$C$12="Higher",IF(J11>=Assumptions!$D$12,1,IF(J11>=Assumptions!$E$12,2,IF(J11>=Assumptions!$F$12,3,IF(J11>=Assumptions!$G$12,4,5)))),IF(J11<=Assumptions!$D$12,1,IF(J11<=Assumptions!$E$12,2,IF(J11<=Assumptions!$F$12,3,IF(J11<=Assumptions!$G$12,4,5))))),5) -> 1 | T11: =IF(ISNUMBER(K11),IF(Assumptions!$C$13="Higher",IF(K11>=Assumptions!$D$13,1,IF(K11>=Assumptions!$E$13,2,IF(K11>=Assumptions!$F$13,3,IF(K11>=Assumptions!$G$13,4,5)))),IF(K11<=Assumptions!$D$13,1,IF(K11<=Assumptions!$E$13,2,IF(K11<=Assumptions!$F$13,3,IF(K11<=Assumptions!$G$13,4,5))))),5) -> 5 | U11: =L11*Assumptions!$H$5+M11*Assumptions!$H$6+N11*Assumptions!$H$7+O11*Assumptions!$H$8+P11*Assumptions!$H$9+Q11*Assumptions!$H$10+R11*Assumptions!$H$11+S11*Assumptions!$H$12+T11*Assumptions!$H$13 -> 3.1 | V11: =INDEX(Assumptions!$B$19:$B$30,MATCH(U11,Assumptions!$A$19:$A$30,1)) -> BB | W11: =RANK(U11,$U$5:$U$16,1) -> 10
A12: ='Peer Data'!A12 -> ARBS | B12: ='Peer Data'!B12 -> Arab Bank Syria | C12: =IF('Peer Data'!N12<=0,"n.m.",'Peer Data'!M12/'Peer Data'!N12) -> 0.45952915 | D12: =IF('Peer Data'!N12<=0,"n.m.",'Peer Data'!L12/'Peer Data'!N12) -> 0.4570441 | E12: =IF('Peer Data'!F12<=0,"n.m.",'Peer Data'!G12/'Peer Data'!F12) -> 0.94203366 | F12: =IF(('Peer Data'!L12+'Peer Data'!H12)<=0,"n.m.",'Peer Data'!G12/('Peer Data'!L12+'Peer Data'!H12)) -> 1.3604002 | G12: =IF('Peer Data'!N12<=0,"n.m.",'Peer Data'!Q12*12/Inputs!$C$7/'Peer Data'!N12) -> -0.0046694179 | H12: =IF('Peer Data'!N12<=0,"n.m.",('Peer Data'!O12-'Peer Data'!P12)*12/Inputs!$C$7/'Peer Data'!N12) -> -0.0047100555 | I12: =IF('Peer Data'!D12<=0,"n.m.",('Peer Data'!K12-'Peer Data'!I12-'Peer Data'!J12-'Peer Data'!E12)/'Peer Data'!D12) -> -0.22525297 | J12: =IF('Peer Data'!I12<=0,"n.m.",'Peer Data'!E12/'Peer Data'!I12) -> 0.6437591 | K12: =IF('Peer Data'!O12<=0,"n.m.",'Peer Data'!P12/'Peer Data'!O12) -> 1.1402074 | L12: =IF(ISNUMBER(C12),IF(Assumptions!$C$5="Higher",IF(C12>=Assumptions!$D$5,1,IF(C12>=Assumptions!$E$5,2,IF(C12>=Assumptions!$F$5,3,IF(C12>=Assumptions!$G$5,4,5)))),IF(C12<=Assumptions!$D$5,1,IF(C12<=Assumptions!$E$5,2,IF(C12<=Assumptions!$F$5,3,IF(C12<=Assumptions!$G$5,4,5))))),5) -> 1 | M12: =IF(ISNUMBER(D12),IF(Assumptions!$C$6="Higher",IF(D12>=Assumptions!$D$6,1,IF(D12>=Assumptions!$E$6,2,IF(D12>=Assumptions!$F$6,3,IF(D12>=Assumptions!$G$6,4,5)))),IF(D12<=Assumptions!$D$6,1,IF(D12<=Assumptions!$E$6,2,IF(D12<=Assumptions!$F$6,3,IF(D12<=Assumptions!$G$6,4,5))))),5) -> 1 | N12: =IF(ISNUMBER(E12),IF(Assumptions!$C$7="Higher",IF(E12>=Assumptions!$D$7,1,IF(E12>=Assumptions!$E$7,2,IF(E12>=Assumptions!$F$7,3,IF(E12>=Assumptions!$G$7,4,5)))),IF(E12<=Assumptions!$D$7,1,IF(E12<=Assumptions!$E$7,2,IF(E12<=Assumptions!$F$7,3,IF(E12<=Assumptions!$G$7,4,5))))),5) -> 5 | O12: =IF(ISNUMBER(F12),IF(Assumptions!$C$8="Higher",IF(F12>=Assumptions!$D$8,1,IF(F12>=Assumptions!$E$8,2,IF(F12>=Assumptions!$F$8,3,IF(F12>=Assumptions!$G$8,4,5)))),IF(F12<=Assumptions!$D$8,1,IF(F12<=Assumptions!$E$8,2,IF(F12<=Assumptions!$F$8,3,IF(F12<=Assumptions!$G$8,4,5))))),5) -> 5 | P12: =IF(ISNUMBER(G12),IF(Assumptions!$C$9="Higher",IF(G12>=Assumptions!$D$9,1,IF(G12>=Assumptions!$E$9,2,IF(G12>=Assumptions!$F$9,3,IF(G12>=Assumptions!$G$9,4,5)))),IF(G12<=Assumptions!$D$9,1,IF(G12<=Assumptions!$E$9,2,IF(G12<=Assumptions!$F$9,3,IF(G12<=Assumptions!$G$9,4,5))))),5) -> 5 | Q12: =IF(ISNUMBER(H12),IF(Assumptions!$C$10="Higher",IF(H12>=Assumptions!$D$10,1,IF(H12>=Assumptions!$E$10,2,IF(H12>=Assumptions!$F$10,3,IF(H12>=Assumptions!$G$10,4,5)))),IF(H12<=Assumptions!$D$10,1,IF(H12<=Assumptions!$E$10,2,IF(H12<=Assumptions!$F$10,3,IF(H12<=Assumptions!$G$10,4,5))))),5) -> 5 | R12: =IF(ISNUMBER(I12),IF(Assumptions!$C$11="Higher",IF(I12>=Assumptions!$D$11,1,IF(I12>=Assumptions!$E$11,2,IF(I12>=Assumptions!$F$11,3,IF(I12>=Assumptions!$G$11,4,5)))),IF(I12<=Assumptions!$D$11,1,IF(I12<=Assumptions!$E$11,2,IF(I12<=Assumptions!$F$11,3,IF(I12<=Assumptions!$G$11,4,5))))),5) -> 1 | S12: =IF(ISNUMBER(J12),IF(Assumptions!$C$12="Higher",IF(J12>=Assumptions!$D$12,1,IF(J12>=Assumptions!$E$12,2,IF(J12>=Assumptions!$F$12,3,IF(J12>=Assumptions!$G$12,4,5)))),IF(J12<=Assumptions!$D$12,1,IF(J12<=Assumptions!$E$12,2,IF(J12<=Assumptions!$F$12,3,IF(J12<=Assumptions!$G$12,4,5))))),5) -> 1 | T12: =IF(ISNUMBER(K12),IF(Assumptions!$C$13="Higher",IF(K12>=Assumptions!$D$13,1,IF(K12>=Assumptions!$E$13,2,IF(K12>=Assumptions!$F$13,3,IF(K12>=Assumptions!$G$13,4,5)))),IF(K12<=Assumptions!$D$13,1,IF(K12<=Assumptions!$E$13,2,IF(K12<=Assumptions!$F$13,3,IF(K12<=Assumptions!$G$13,4,5))))),5) -> 5 | U12: =L12*Assumptions!$H$5+M12*Assumptions!$H$6+N12*Assumptions!$H$7+O12*Assumptions!$H$8+P12*Assumptions!$H$9+Q12*Assumptions!$H$10+R12*Assumptions!$H$11+S12*Assumptions!$H$12+T12*Assumptions!$H$13 -> 3.4 | V12: =INDEX(Assumptions!$B$19:$B$30,MATCH(U12,Assumptions!$A$19:$A$30,1)) -> BB- | W12: =RANK(U12,$U$5:$U$16,1) -> 12
A13: ='Peer Data'!A13 -> BBS | B13: ='Peer Data'!B13 -> Shahba Bank (ex-Byblos) | C13: =IF('Peer Data'!N13<=0,"n.m.",'Peer Data'!M13/'Peer Data'!N13) -> 0.50969394 | D13: =IF('Peer Data'!N13<=0,"n.m.",'Peer Data'!L13/'Peer Data'!N13) -> 0.58040565 | E13: =IF('Peer Data'!F13<=0,"n.m.",'Peer Data'!G13/'Peer Data'!F13) -> 0.77307046 | F13: =IF(('Peer Data'!L13+'Peer Data'!H13)<=0,"n.m.",'Peer Data'!G13/('Peer Data'!L13+'Peer Data'!H13)) -> 0.44216575 | G13: =IF('Peer Data'!N13<=0,"n.m.",'Peer Data'!Q13*12/Inputs!$C$7/'Peer Data'!N13) -> -0.034743895 | H13: =IF('Peer Data'!N13<=0,"n.m.",('Peer Data'!O13-'Peer Data'!P13)*12/Inputs!$C$7/'Peer Data'!N13) -> -0.016098814 | I13: =IF('Peer Data'!D13<=0,"n.m.",('Peer Data'!K13-'Peer Data'!I13-'Peer Data'!J13-'Peer Data'!E13)/'Peer Data'!D13) -> -0.69569085 | J13: =IF('Peer Data'!I13<=0,"n.m.",'Peer Data'!E13/'Peer Data'!I13) -> 2.7471717 | K13: =IF('Peer Data'!O13<=0,"n.m.",'Peer Data'!P13/'Peer Data'!O13) -> 2.0022697 | L13: =IF(ISNUMBER(C13),IF(Assumptions!$C$5="Higher",IF(C13>=Assumptions!$D$5,1,IF(C13>=Assumptions!$E$5,2,IF(C13>=Assumptions!$F$5,3,IF(C13>=Assumptions!$G$5,4,5)))),IF(C13<=Assumptions!$D$5,1,IF(C13<=Assumptions!$E$5,2,IF(C13<=Assumptions!$F$5,3,IF(C13<=Assumptions!$G$5,4,5))))),5) -> 1 | M13: =IF(ISNUMBER(D13),IF(Assumptions!$C$6="Higher",IF(D13>=Assumptions!$D$6,1,IF(D13>=Assumptions!$E$6,2,IF(D13>=Assumptions!$F$6,3,IF(D13>=Assumptions!$G$6,4,5)))),IF(D13<=Assumptions!$D$6,1,IF(D13<=Assumptions!$E$6,2,IF(D13<=Assumptions!$F$6,3,IF(D13<=Assumptions!$G$6,4,5))))),5) -> 1 | N13: =IF(ISNUMBER(E13),IF(Assumptions!$C$7="Higher",IF(E13>=Assumptions!$D$7,1,IF(E13>=Assumptions!$E$7,2,IF(E13>=Assumptions!$F$7,3,IF(E13>=Assumptions!$G$7,4,5)))),IF(E13<=Assumptions!$D$7,1,IF(E13<=Assumptions!$E$7,2,IF(E13<=Assumptions!$F$7,3,IF(E13<=Assumptions!$G$7,4,5))))),5) -> 5 | O13: =IF(ISNUMBER(F13),IF(Assumptions!$C$8="Higher",IF(F13>=Assumptions!$D$8,1,IF(F13>=Assumptions!$E$8,2,IF(F13>=Assumptions!$F$8,3,IF(F13>=Assumptions!$G$8,4,5)))),IF(F13<=Assumptions!$D$8,1,IF(F13<=Assumptions!$E$8,2,IF(F13<=Assumptions!$F$8,3,IF(F13<=Assumptions!$G$8,4,5))))),5) -> 3 | P13: =IF(ISNUMBER(G13),IF(Assumptions!$C$9="Higher",IF(G13>=Assumptions!$D$9,1,IF(G13>=Assumptions!$E$9,2,IF(G13>=Assumptions!$F$9,3,IF(G13>=Assumptions!$G$9,4,5)))),IF(G13<=Assumptions!$D$9,1,IF(G13<=Assumptions!$E$9,2,IF(G13<=Assumptions!$F$9,3,IF(G13<=Assumptions!$G$9,4,5))))),5) -> 5 | Q13: =IF(ISNUMBER(H13),IF(Assumptions!$C$10="Higher",IF(H13>=Assumptions!$D$10,1,IF(H13>=Assumptions!$E$10,2,IF(H13>=Assumptions!$F$10,3,IF(H13>=Assumptions!$G$10,4,5)))),IF(H13<=Assumptions!$D$10,1,IF(H13<=Assumptions!$E$10,2,IF(H13<=Assumptions!$F$10,3,IF(H13<=Assumptions!$G$10,4,5))))),5) -> 5 | R13: =IF(ISNUMBER(I13),IF(Assumptions!$C$11="Higher",IF(I13>=Assumptions!$D$11,1,IF(I13>=Assumptions!$E$11,2,IF(I13>=Assumptions!$F$11,3,IF(I13>=Assumptions!$G$11,4,5)))),IF(I13<=Assumptions!$D$11,1,IF(I13<=Assumptions!$E$11,2,IF(I13<=Assumptions!$F$11,3,IF(I13<=Assumptions!$G$11,4,5))))),5) -> 1 | S13: =IF(ISNUMBER(J13),IF(Assumptions!$C$12="Higher",IF(J13>=Assumptions!$D$12,1,IF(J13>=Assumptions!$E$12,2,IF(J13>=Assumptions!$F$12,3,IF(J13>=Assumptions!$G$12,4,5)))),IF(J13<=Assumptions!$D$12,1,IF(J13<=Assumptions!$E$12,2,IF(J13<=Assumptions!$F$12,3,IF(J13<=Assumptions!$G$12,4,5))))),5) -> 1 | T13: =IF(ISNUMBER(K13),IF(Assumptions!$C$13="Higher",IF(K13>=Assumptions!$D$13,1,IF(K13>=Assumptions!$E$13,2,IF(K13>=Assumptions!$F$13,3,IF(K13>=Assumptions!$G$13,4,5)))),IF(K13<=Assumptions!$D$13,1,IF(K13<=Assumptions!$E$13,2,IF(K13<=Assumptions!$F$13,3,IF(K13<=Assumptions!$G$13,4,5))))),5) -> 5 | U13: =L13*Assumptions!$H$5+M13*Assumptions!$H$6+N13*Assumptions!$H$7+O13*Assumptions!$H$8+P13*Assumptions!$H$9+Q13*Assumptions!$H$10+R13*Assumptions!$H$11+S13*Assumptions!$H$12+T13*Assumptions!$H$13 -> 3.1 | V13: =INDEX(Assumptions!$B$19:$B$30,MATCH(U13,Assumptions!$A$19:$A$30,1)) -> BB | W13: =RANK(U13,$U$5:$U$16,1) -> 10
A14: ='Peer Data'!A14 -> BOJS | B14: ='Peer Data'!B14 -> Bank of Jordan Syria | C14: =IF('Peer Data'!N14<=0,"n.m.",'Peer Data'!M14/'Peer Data'!N14) -> 1.342381 | D14: =IF('Peer Data'!N14<=0,"n.m.",'Peer Data'!L14/'Peer Data'!N14) -> 1.3158686 | E14: =IF('Peer Data'!F14<=0,"n.m.",'Peer Data'!G14/'Peer Data'!F14) -> 0.068979992 | F14: =IF(('Peer Data'!L14+'Peer Data'!H14)<=0,"n.m.",'Peer Data'!G14/('Peer Data'!L14+'Peer Data'!H14)) -> 0.04119319 | G14: =IF('Peer Data'!N14<=0,"n.m.",'Peer Data'!Q14*12/Inputs!$C$7/'Peer Data'!N14) -> 0.036370759 | H14: =IF('Peer Data'!N14<=0,"n.m.",('Peer Data'!O14-'Peer Data'!P14)*12/Inputs!$C$7/'Peer Data'!N14) -> 0.09650458 | I14: =IF('Peer Data'!D14<=0,"n.m.",('Peer Data'!K14-'Peer Data'!I14-'Peer Data'!J14-'Peer Data'!E14)/'Peer Data'!D14) -> -0.62169985 | J14: =IF('Peer Data'!I14<=0,"n.m.",'Peer Data'!E14/'Peer Data'!I14) -> 1.2111285 | K14: =IF('Peer Data'!O14<=0,"n.m.",'Peer Data'!P14/'Peer Data'!O14) -> 0.47076485 | L14: =IF(ISNUMBER(C14),IF(Assumptions!$C$5="Higher",IF(C14>=Assumptions!$D$5,1,IF(C14>=Assumptions!$E$5,2,IF(C14>=Assumptions!$F$5,3,IF(C14>=Assumptions!$G$5,4,5)))),IF(C14<=Assumptions!$D$5,1,IF(C14<=Assumptions!$E$5,2,IF(C14<=Assumptions!$F$5,3,IF(C14<=Assumptions!$G$5,4,5))))),5) -> 1 | M14: =IF(ISNUMBER(D14),IF(Assumptions!$C$6="Higher",IF(D14>=Assumptions!$D$6,1,IF(D14>=Assumptions!$E$6,2,IF(D14>=Assumptions!$F$6,3,IF(D14>=Assumptions!$G$6,4,5)))),IF(D14<=Assumptions!$D$6,1,IF(D14<=Assumptions!$E$6,2,IF(D14<=Assumptions!$F$6,3,IF(D14<=Assumptions!$G$6,4,5))))),5) -> 1 | N14: =IF(ISNUMBER(E14),IF(Assumptions!$C$7="Higher",IF(E14>=Assumptions!$D$7,1,IF(E14>=Assumptions!$E$7,2,IF(E14>=Assumptions!$F$7,3,IF(E14>=Assumptions!$G$7,4,5)))),IF(E14<=Assumptions!$D$7,1,IF(E14<=Assumptions!$E$7,2,IF(E14<=Assumptions!$F$7,3,IF(E14<=Assumptions!$G$7,4,5))))),5) -> 3 | O14: =IF(ISNUMBER(F14),IF(Assumptions!$C$8="Higher",IF(F14>=Assumptions!$D$8,1,IF(F14>=Assumptions!$E$8,2,IF(F14>=Assumptions!$F$8,3,IF(F14>=Assumptions!$G$8,4,5)))),IF(F14<=Assumptions!$D$8,1,IF(F14<=Assumptions!$E$8,2,IF(F14<=Assumptions!$F$8,3,IF(F14<=Assumptions!$G$8,4,5))))),5) -> 1 | P14: =IF(ISNUMBER(G14),IF(Assumptions!$C$9="Higher",IF(G14>=Assumptions!$D$9,1,IF(G14>=Assumptions!$E$9,2,IF(G14>=Assumptions!$F$9,3,IF(G14>=Assumptions!$G$9,4,5)))),IF(G14<=Assumptions!$D$9,1,IF(G14<=Assumptions!$E$9,2,IF(G14<=Assumptions!$F$9,3,IF(G14<=Assumptions!$G$9,4,5))))),5) -> 1 | Q14: =IF(ISNUMBER(H14),IF(Assumptions!$C$10="Higher",IF(H14>=Assumptions!$D$10,1,IF(H14>=Assumptions!$E$10,2,IF(H14>=Assumptions!$F$10,3,IF(H14>=Assumptions!$G$10,4,5)))),IF(H14<=Assumptions!$D$10,1,IF(H14<=Assumptions!$E$10,2,IF(H14<=Assumptions!$F$10,3,IF(H14<=Assumptions!$G$10,4,5))))),5) -> 1 | R14: =IF(ISNUMBER(I14),IF(Assumptions!$C$11="Higher",IF(I14>=Assumptions!$D$11,1,IF(I14>=Assumptions!$E$11,2,IF(I14>=Assumptions!$F$11,3,IF(I14>=Assumptions!$G$11,4,5)))),IF(I14<=Assumptions!$D$11,1,IF(I14<=Assumptions!$E$11,2,IF(I14<=Assumptions!$F$11,3,IF(I14<=Assumptions!$G$11,4,5))))),5) -> 1 | S14: =IF(ISNUMBER(J14),IF(Assumptions!$C$12="Higher",IF(J14>=Assumptions!$D$12,1,IF(J14>=Assumptions!$E$12,2,IF(J14>=Assumptions!$F$12,3,IF(J14>=Assumptions!$G$12,4,5)))),IF(J14<=Assumptions!$D$12,1,IF(J14<=Assumptions!$E$12,2,IF(J14<=Assumptions!$F$12,3,IF(J14<=Assumptions!$G$12,4,5))))),5) -> 1 | T14: =IF(ISNUMBER(K14),IF(Assumptions!$C$13="Higher",IF(K14>=Assumptions!$D$13,1,IF(K14>=Assumptions!$E$13,2,IF(K14>=Assumptions!$F$13,3,IF(K14>=Assumptions!$G$13,4,5)))),IF(K14<=Assumptions!$D$13,1,IF(K14<=Assumptions!$E$13,2,IF(K14<=Assumptions!$F$13,3,IF(K14<=Assumptions!$G$13,4,5))))),5) -> 2 | U14: =L14*Assumptions!$H$5+M14*Assumptions!$H$6+N14*Assumptions!$H$7+O14*Assumptions!$H$8+P14*Assumptions!$H$9+Q14*Assumptions!$H$10+R14*Assumptions!$H$11+S14*Assumptions!$H$12+T14*Assumptions!$H$13 -> 1.4 | V14: =INDEX(Assumptions!$B$19:$B$30,MATCH(U14,Assumptions!$A$19:$A$30,1)) -> A | W14: =RANK(U14,$U$5:$U$16,1) -> 4
A15: ='Peer Data'!A15 -> Shrq | B15: ='Peer Data'!B15 -> Bank Al Sharq | C15: =IF('Peer Data'!N15<=0,"n.m.",'Peer Data'!M15/'Peer Data'!N15) -> 1.3244683 | D15: =IF('Peer Data'!N15<=0,"n.m.",'Peer Data'!L15/'Peer Data'!N15) -> 1.3787426 | E15: =IF('Peer Data'!F15<=0,"n.m.",'Peer Data'!G15/'Peer Data'!F15) -> 0.13645114 | F15: =IF(('Peer Data'!L15+'Peer Data'!H15)<=0,"n.m.",'Peer Data'!G15/('Peer Data'!L15+'Peer Data'!H15)) -> 0.045465182 | G15: =IF('Peer Data'!N15<=0,"n.m.",'Peer Data'!Q15*12/Inputs!$C$7/'Peer Data'!N15) -> 0.051008378 | H15: =IF('Peer Data'!N15<=0,"n.m.",('Peer Data'!O15-'Peer Data'!P15)*12/Inputs!$C$7/'Peer Data'!N15) -> 0.064072168 | I15: =IF('Peer Data'!D15<=0,"n.m.",('Peer Data'!K15-'Peer Data'!I15-'Peer Data'!J15-'Peer Data'!E15)/'Peer Data'!D15) -> -0.76325396 | J15: =IF('Peer Data'!I15<=0,"n.m.",'Peer Data'!E15/'Peer Data'!I15) -> 1.5707227 | K15: =IF('Peer Data'!O15<=0,"n.m.",'Peer Data'!P15/'Peer Data'!O15) -> 0.62826139 | L15: =IF(ISNUMBER(C15),IF(Assumptions!$C$5="Higher",IF(C15>=Assumptions!$D$5,1,IF(C15>=Assumptions!$E$5,2,IF(C15>=Assumptions!$F$5,3,IF(C15>=Assumptions!$G$5,4,5)))),IF(C15<=Assumptions!$D$5,1,IF(C15<=Assumptions!$E$5,2,IF(C15<=Assumptions!$F$5,3,IF(C15<=Assumptions!$G$5,4,5))))),5) -> 1 | M15: =IF(ISNUMBER(D15),IF(Assumptions!$C$6="Higher",IF(D15>=Assumptions!$D$6,1,IF(D15>=Assumptions!$E$6,2,IF(D15>=Assumptions!$F$6,3,IF(D15>=Assumptions!$G$6,4,5)))),IF(D15<=Assumptions!$D$6,1,IF(D15<=Assumptions!$E$6,2,IF(D15<=Assumptions!$F$6,3,IF(D15<=Assumptions!$G$6,4,5))))),5) -> 1 | N15: =IF(ISNUMBER(E15),IF(Assumptions!$C$7="Higher",IF(E15>=Assumptions!$D$7,1,IF(E15>=Assumptions!$E$7,2,IF(E15>=Assumptions!$F$7,3,IF(E15>=Assumptions!$G$7,4,5)))),IF(E15<=Assumptions!$D$7,1,IF(E15<=Assumptions!$E$7,2,IF(E15<=Assumptions!$F$7,3,IF(E15<=Assumptions!$G$7,4,5))))),5) -> 4 | O15: =IF(ISNUMBER(F15),IF(Assumptions!$C$8="Higher",IF(F15>=Assumptions!$D$8,1,IF(F15>=Assumptions!$E$8,2,IF(F15>=Assumptions!$F$8,3,IF(F15>=Assumptions!$G$8,4,5)))),IF(F15<=Assumptions!$D$8,1,IF(F15<=Assumptions!$E$8,2,IF(F15<=Assumptions!$F$8,3,IF(F15<=Assumptions!$G$8,4,5))))),5) -> 1 | P15: =IF(ISNUMBER(G15),IF(Assumptions!$C$9="Higher",IF(G15>=Assumptions!$D$9,1,IF(G15>=Assumptions!$E$9,2,IF(G15>=Assumptions!$F$9,3,IF(G15>=Assumptions!$G$9,4,5)))),IF(G15<=Assumptions!$D$9,1,IF(G15<=Assumptions!$E$9,2,IF(G15<=Assumptions!$F$9,3,IF(G15<=Assumptions!$G$9,4,5))))),5) -> 1 | Q15: =IF(ISNUMBER(H15),IF(Assumptions!$C$10="Higher",IF(H15>=Assumptions!$D$10,1,IF(H15>=Assumptions!$E$10,2,IF(H15>=Assumptions!$F$10,3,IF(H15>=Assumptions!$G$10,4,5)))),IF(H15<=Assumptions!$D$10,1,IF(H15<=Assumptions!$E$10,2,IF(H15<=Assumptions!$F$10,3,IF(H15<=Assumptions!$G$10,4,5))))),5) -> 1 | R15: =IF(ISNUMBER(I15),IF(Assumptions!$C$11="Higher",IF(I15>=Assumptions!$D$11,1,IF(I15>=Assumptions!$E$11,2,IF(I15>=Assumptions!$F$11,3,IF(I15>=Assumptions!$G$11,4,5)))),IF(I15<=Assumptions!$D$11,1,IF(I15<=Assumptions!$E$11,2,IF(I15<=Assumptions!$F$11,3,IF(I15<=Assumptions!$G$11,4,5))))),5) -> 1 | S15: =IF(ISNUMBER(J15),IF(Assumptions!$C$12="Higher",IF(J15>=Assumptions!$D$12,1,IF(J15>=Assumptions!$E$12,2,IF(J15>=Assumptions!$F$12,3,IF(J15>=Assumptions!$G$12,4,5)))),IF(J15<=Assumptions!$D$12,1,IF(J15<=Assumptions!$E$12,2,IF(J15<=Assumptions!$F$12,3,IF(J15<=Assumptions!$G$12,4,5))))),5) -> 1 | T15: =IF(ISNUMBER(K15),IF(Assumptions!$C$13="Higher",IF(K15>=Assumptions!$D$13,1,IF(K15>=Assumptions!$E$13,2,IF(K15>=Assumptions!$F$13,3,IF(K15>=Assumptions!$G$13,4,5)))),IF(K15<=Assumptions!$D$13,1,IF(K15<=Assumptions!$E$13,2,IF(K15<=Assumptions!$F$13,3,IF(K15<=Assumptions!$G$13,4,5))))),5) -> 3 | U15: =L15*Assumptions!$H$5+M15*Assumptions!$H$6+N15*Assumptions!$H$7+O15*Assumptions!$H$8+P15*Assumptions!$H$9+Q15*Assumptions!$H$10+R15*Assumptions!$H$11+S15*Assumptions!$H$12+T15*Assumptions!$H$13 -> 1.65 | V15: =INDEX(Assumptions!$B$19:$B$30,MATCH(U15,Assumptions!$A$19:$A$30,1)) -> A | W15: =RANK(U15,$U$5:$U$16,1) -> 6
A16: ='Peer Data'!A16 -> NIB | B16: ='Peer Data'!B16 -> National Islamic Bank | C16: =IF('Peer Data'!N16<=0,"n.m.",'Peer Data'!M16/'Peer Data'!N16) -> 0.97506971 | D16: =IF('Peer Data'!N16<=0,"n.m.",'Peer Data'!L16/'Peer Data'!N16) -> 1.090911 | E16: =IF('Peer Data'!F16<=0,"n.m.",'Peer Data'!G16/'Peer Data'!F16) -> 0.14877466 | F16: =IF(('Peer Data'!L16+'Peer Data'!H16)<=0,"n.m.",'Peer Data'!G16/('Peer Data'!L16+'Peer Data'!H16)) -> 0.26703416 | G16: =IF('Peer Data'!N16<=0,"n.m.",'Peer Data'!Q16*12/Inputs!$C$7/'Peer Data'!N16) -> 0.0059704139 | H16: =IF('Peer Data'!N16<=0,"n.m.",('Peer Data'!O16-'Peer Data'!P16)*12/Inputs!$C$7/'Peer Data'!N16) -> 0.084774336 | I16: =IF('Peer Data'!D16<=0,"n.m.",('Peer Data'!K16-'Peer Data'!I16-'Peer Data'!J16-'Peer Data'!E16)/'Peer Data'!D16) -> -0.74893567 | J16: =IF('Peer Data'!I16<=0,"n.m.",'Peer Data'!E16/'Peer Data'!I16) -> 1.0116101 | K16: =IF('Peer Data'!O16<=0,"n.m.",'Peer Data'!P16/'Peer Data'!O16) -> 0.86304607 | L16: =IF(ISNUMBER(C16),IF(Assumptions!$C$5="Higher",IF(C16>=Assumptions!$D$5,1,IF(C16>=Assumptions!$E$5,2,IF(C16>=Assumptions!$F$5,3,IF(C16>=Assumptions!$G$5,4,5)))),IF(C16<=Assumptions!$D$5,1,IF(C16<=Assumptions!$E$5,2,IF(C16<=Assumptions!$F$5,3,IF(C16<=Assumptions!$G$5,4,5))))),5) -> 1 | M16: =IF(ISNUMBER(D16),IF(Assumptions!$C$6="Higher",IF(D16>=Assumptions!$D$6,1,IF(D16>=Assumptions!$E$6,2,IF(D16>=Assumptions!$F$6,3,IF(D16>=Assumptions!$G$6,4,5)))),IF(D16<=Assumptions!$D$6,1,IF(D16<=Assumptions!$E$6,2,IF(D16<=Assumptions!$F$6,3,IF(D16<=Assumptions!$G$6,4,5))))),5) -> 1 | N16: =IF(ISNUMBER(E16),IF(Assumptions!$C$7="Higher",IF(E16>=Assumptions!$D$7,1,IF(E16>=Assumptions!$E$7,2,IF(E16>=Assumptions!$F$7,3,IF(E16>=Assumptions!$G$7,4,5)))),IF(E16<=Assumptions!$D$7,1,IF(E16<=Assumptions!$E$7,2,IF(E16<=Assumptions!$F$7,3,IF(E16<=Assumptions!$G$7,4,5))))),5) -> 4 | O16: =IF(ISNUMBER(F16),IF(Assumptions!$C$8="Higher",IF(F16>=Assumptions!$D$8,1,IF(F16>=Assumptions!$E$8,2,IF(F16>=Assumptions!$F$8,3,IF(F16>=Assumptions!$G$8,4,5)))),IF(F16<=Assumptions!$D$8,1,IF(F16<=Assumptions!$E$8,2,IF(F16<=Assumptions!$F$8,3,IF(F16<=Assumptions!$G$8,4,5))))),5) -> 3 | P16: =IF(ISNUMBER(G16),IF(Assumptions!$C$9="Higher",IF(G16>=Assumptions!$D$9,1,IF(G16>=Assumptions!$E$9,2,IF(G16>=Assumptions!$F$9,3,IF(G16>=Assumptions!$G$9,4,5)))),IF(G16<=Assumptions!$D$9,1,IF(G16<=Assumptions!$E$9,2,IF(G16<=Assumptions!$F$9,3,IF(G16<=Assumptions!$G$9,4,5))))),5) -> 4 | Q16: =IF(ISNUMBER(H16),IF(Assumptions!$C$10="Higher",IF(H16>=Assumptions!$D$10,1,IF(H16>=Assumptions!$E$10,2,IF(H16>=Assumptions!$F$10,3,IF(H16>=Assumptions!$G$10,4,5)))),IF(H16<=Assumptions!$D$10,1,IF(H16<=Assumptions!$E$10,2,IF(H16<=Assumptions!$F$10,3,IF(H16<=Assumptions!$G$10,4,5))))),5) -> 1 | R16: =IF(ISNUMBER(I16),IF(Assumptions!$C$11="Higher",IF(I16>=Assumptions!$D$11,1,IF(I16>=Assumptions!$E$11,2,IF(I16>=Assumptions!$F$11,3,IF(I16>=Assumptions!$G$11,4,5)))),IF(I16<=Assumptions!$D$11,1,IF(I16<=Assumptions!$E$11,2,IF(I16<=Assumptions!$F$11,3,IF(I16<=Assumptions!$G$11,4,5))))),5) -> 1 | S16: =IF(ISNUMBER(J16),IF(Assumptions!$C$12="Higher",IF(J16>=Assumptions!$D$12,1,IF(J16>=Assumptions!$E$12,2,IF(J16>=Assumptions!$F$12,3,IF(J16>=Assumptions!$G$12,4,5)))),IF(J16<=Assumptions!$D$12,1,IF(J16<=Assumptions!$E$12,2,IF(J16<=Assumptions!$F$12,3,IF(J16<=Assumptions!$G$12,4,5))))),5) -> 1 | T16: =IF(ISNUMBER(K16),IF(Assumptions!$C$13="Higher",IF(K16>=Assumptions!$D$13,1,IF(K16>=Assumptions!$E$13,2,IF(K16>=Assumptions!$F$13,3,IF(K16>=Assumptions!$G$13,4,5)))),IF(K16<=Assumptions!$D$13,1,IF(K16<=Assumptions!$E$13,2,IF(K16<=Assumptions!$F$13,3,IF(K16<=Assumptions!$G$13,4,5))))),5) -> 5 | U16: =L16*Assumptions!$H$5+M16*Assumptions!$H$6+N16*Assumptions!$H$7+O16*Assumptions!$H$8+P16*Assumptions!$H$9+Q16*Assumptions!$H$10+R16*Assumptions!$H$11+S16*Assumptions!$H$12+T16*Assumptions!$H$13 -> 2.45 | V16: =INDEX(Assumptions!$B$19:$B$30,MATCH(U16,Assumptions!$A$19:$A$30,1)) -> BBB- | W16: =RANK(U16,$U$5:$U$16,1) -> 8

Sheet Assumptions
A1: Scoring assumptions (editable)
A2: Author's illustrative calibration. A = 1 point (strongest) … E = 5 points. A ratio is graded A if it meets the A cut-off, B if it meets the B cut-off, and so on; otherwise E.
A4: Ratio | B4: Category | C4: Better when | D4: A cut-off | E4: B cut-off | F4: C cut-off | G4: D cut-off | H4: Weight | I4: Definition
A5: Capital adequacy ratio (CAR) | B5: Capital | C5: Higher | D5: 0.2 | E5: 0.15 | F5: 0.125 | G5: 0.1 | H5: 0.1 | I5: Regulatory capital ÷ risk-weighted assets
A6: Equity / RWA | B6: Capital | C6: Higher | D6: 0.15 | E6: 0.12 | F6: 0.1 | G6: 0.08 | H6: 0.1 | I6: Total equity ÷ risk-weighted assets (loss-absorption buffer)
A7: NPL ratio | B7: Asset quality | C7: Lower | D7: 0.03 | E7: 0.06 | F7: 0.1 | G7: 0.2 | H7: 0.15 | I7: Non-performing loans ÷ gross loans
A8: NPL / (equity + ECL) | B8: Asset quality | C8: Lower | D8: 0.1 | E8: 0.25 | F8: 0.5 | G8: 1 | H8: 0.15 | I8: Unprovisioned-risk test ("Texas ratio" style); n.m. scores E
A9: Net income / RWA (annualised) | B9: Profitability | C9: Higher | D9: 0.025 | E9: 0.015 | F9: 0.0075 | G9: 0 | H9: 0.1 | I9: Adjusted net income × 12 / months ÷ RWA
